<?xml version="1.0" ?>
<!-- =================================================================================== -->
<!-- |    This document was autogenerated by xacro from /root/itr_ws/src/hebi_robot/urdf/HEBI.urdf.xacro | -->
<!-- |    EDITING THIS FILE BY HAND IS NOT RECOMMENDED                                 | -->
<!-- =================================================================================== -->
<robot name="HEBI">
  <!-- Base -->
  <link name="world"/>
  <joint name="world_joint" type="fixed">
    <parent link="world"/>
    <child link="base_link"/>
    <origin rpy="0.0 0.0 0.0" xyz="0.0 0.0 0.0"/>
  </joint>
  <link name="base_link">
    <visual>
      <geometry>
        <mesh filename="package://hebi_robot/my_CAD/chassis-Body.stl" scale="0.01 0.01 0.01"/>
      </geometry>
      <origin rpy="0 0 0" xyz="0 0 0"/>
      <material name="gray">
        <color rgba="0.5 0.5 0.5 1"/>
      </material>
    </visual>
    <collision>
      <geometry>
        <mesh filename="package://hebi_robot/my_CAD/chassis-Body.stl" scale="0.01 0.01 0.01"/>
      </geometry>
      <origin rpy="0 0 0" xyz="0 0 0"/>
    </collision>
    <inertial>
      <mass value="1.0"/>
      <origin xyz="0 0 1"/>
      <inertia ixx="0.01" ixy="0" ixz="0" iyy="0.01" iyz="0" izz="0.01"/>
    </inertial>
  </link>
  <gazebo reference="base_link">
    <gravity>0</gravity>
  </gazebo>

  <!-- blu è Z , verde è Y, rosso è X-->
  <!-- Shoulder -->
  <joint name="rf_shoulder1_joint" type="revolute">
    <parent link="base_link"/>
    <child link="rf_shoulder"/>
    <origin rpy="0 1.5707963267948966 0" xyz="0.075 0.125 0"/>
    <axis xyz="0 0 1"/>
    <limit effort="100" lower="-1.5707963267948966" upper="1.5707963267948966" velocity="10.0"/>
    <dynamics damping="0.5" friction="0.2"/>
  </joint>
  <link name="rf_shoulder">
    <visual>
      <geometry>
        <mesh filename="package://hebi_robot/my_CAD/shoulder.stl" scale="0.01 0.01 0.01"/>
      </geometry>
      <origin rpy="-1.5707963267948966 0 1.5707963267948966" xyz="0 0 0"/>
      <material name="black">
        <color rgba="0 0 0 1"/>
      </material>
    </visual>
    <collision>
      <geometry>
        <mesh filename="package://hebi_robot/my_CAD/shoulder.stl" scale="0.01 0.01 0.01"/>
      </geometry>
    </collision>
    <inertial>
      <mass value="0.5"/>
      <origin xyz="0 0 0"/>
      <inertia ixx="0.01" ixy="0" ixz="0" iyy="0.01" iyz="0" izz="0.01"/>
    </inertial>
  </link>
  <!-- Fixed joint to leg -->
  <joint name="rf_shoulder2_joint" type="fixed">
    <parent link="rf_shoulder"/>
    <child link="rf_leg"/>
    <origin xyz="0 0 0"/>
  </joint>
  <link name="rf_leg">
    <visual>
      <geometry>
        <cylinder length="0.1" radius="0.0125"/>
      </geometry>
      <origin rpy="0 -1.5707963267948966 0" xyz="0.095 0 0"/>
      <material name="silver">
        <color rgba="0.75 0.75 0.75 1"/>
      </material>
    </visual>
    <collision>
      <geometry>
        <cylinder length="0.1" radius="0.01"/>
      </geometry>
    </collision>
    <inertial>
      <mass value="1.0"/>
      <origin xyz="0 0 0"/>
      <inertia ixx="0.02" ixy="0" ixz="0" iyy="0.02" iyz="0" izz="0.02"/>
    </inertial>
  </link>
  <!-- Prismatic suspension -->
  <joint name="rf_suspention_ext_joint" type="prismatic">
    <parent link="rf_leg"/>
    <child link="rf_leg_ext"/>
    <origin xyz="0 0 0"/>
    <axis xyz="1 0 0"/>
    <limit effort="100" lower="0.0" upper="0.075" velocity="1"/>
    <dynamics damping="0.1" friction="0.1"/>
  </joint>
  <link name="rf_leg_ext">
    <visual>
      <geometry>
        <cylinder length="0.1" radius="0.0075"/>
      </geometry>
      <origin rpy="0 1.5707963267948966 0" xyz="0.1 0 0"/>
      <material name="silver">
        <color rgba="0.75 0.75 0.75 1"/>
      </material>
    </visual>
    <collision>
      <geometry>
        <cylinder length="0.1" radius="0.01"/>
      </geometry>
    </collision>
    <inertial>
      <mass value="1.0"/>
      <origin rpy="0 1.5707963267948966 0" xyz="0 0 0"/>
      <inertia ixx="0.02" ixy="0" ixz="0" iyy="0.02" iyz="0" izz="0.02"/>
    </inertial>
  </link>
  <!-- Foot pitch -->
  <joint name="rf_foot_joint_pitch" type="revolute">
    <parent link="rf_leg_ext"/>
    <child link="rf_foot_r"/>
    <origin rpy="0 0 1.5707963267948966" xyz="0.155 0 0"/>
    <axis xyz="0 0 1"/>
    <limit effort="100" lower="-1.0471975511965976" upper="1.0471975511965976" velocity="1.0"/>
    <dynamics damping="0.1" friction="0.1"/>
  </joint>
  <link name="rf_foot_r">
    <visual>
      <geometry>
        <sphere radius="0.01"/>
      </geometry>
      <origin xyz="0 0.0 0"/>
      <material name="silver">
        <color rgba="0.75 0.75 0.75 1"/>
      </material>
    </visual>
    <collision>
      <geometry>
        <sphere radius="0.01"/>
      </geometry>
      <origin xyz="0 0 0"/>
    </collision>
    <inertial>
      <mass value="1.0"/>
      <origin xyz="0 0 0"/>
      <inertia ixx="0.02" ixy="0" ixz="0" iyy="0.02" iyz="0" izz="0.02"/>
    </inertial>
  </link>
  <!-- Foot pitch to fix -->
  <joint name="rf_foot_joint_mid" type="fixed">
    <parent link="rf_foot_r"/>
    <child link="rf_foot_mid"/>
    <origin rpy="0 1.5707963267948966 0" xyz="0 0 0"/>
  </joint>
  <link name="rf_foot_mid">
    <visual>
      <geometry>
        <cylinder length="0.025" radius="0.001"/>
      </geometry>
      <origin rpy="0 1.5707963267948966 0" xyz="-0.015 0 0"/>
      <material name="silver">
        <color rgba="0.75 0.75 0.75 1"/>
      </material>
    </visual>
    <collision>
      <geometry>
        <cylinder length="0.025" radius="0.001"/>
      </geometry>
      <origin rpy="0 1.5707963267948966 0" xyz="-0.015 0 0"/>
    </collision>
    <inertial>
      <mass value="1.0"/>
      <origin xyz="0 0 0"/>
      <inertia ixx="0.02" ixy="0" ixz="0" iyy="0.02" iyz="0" izz="0.02"/>
    </inertial>
  </link>
  <!-- Foot fix to roll -->
  <joint name="rf_foot_joint_mid_2" type="fixed">
    <parent link="rf_foot_mid"/>
    <child link="rf_foot_mid_2"/>
    <origin rpy="0 -1.5707963267948966 0" xyz="-0.025 0 0"/>
  </joint>
  <link name="rf_foot_mid_2">
    <visual>
      <geometry>
        <sphere radius="0.005"/>
      </geometry>
      <origin xyz="0 0.0 0"/>
      <material name="silver">
        <color rgba="0.75 0.75 0.75 1"/>
      </material>
    </visual>
    <collision>
      <geometry>
        <sphere radius="0.005"/>
      </geometry>
      <origin xyz="0 0 0"/>
    </collision>
    <inertial>
      <mass value="1.0"/>
      <origin xyz="0 0 0"/>
      <inertia ixx="0.02" ixy="0" ixz="0" iyy="0.02" iyz="0" izz="0.02"/>
    </inertial>
  </link>
  <!-- Foot roll -->
  <joint name="rf_foot_joint_roll" type="revolute">
    <parent link="rf_foot_mid_2"/>
    <child link="rf_foot"/>
    <origin xyz="0 0 0"/>
    <axis xyz="1 0 0"/>
    <limit effort="100" lower="-0.39269908169872414" upper="0.39269908169872414" velocity="1.0"/>
    <dynamics damping="0.1" friction="0.1"/>
  </joint>
  <link name="rf_foot">
    <visual>
      <geometry>
        <cylinder length="0.1" radius="0.001"/>
      </geometry>
      <origin rpy="0 -1.5707963267948966 0" xyz="0.05 0 0"/>
      <material name="silver">
        <color rgba="0.75 0.75 0.75 1"/>
      </material>
    </visual>
    <collision>
      <geometry>
        <cylinder length="0.1" radius="0.015"/>
      </geometry>
      <origin xyz="0.05 0.0 -0.025"/>
    </collision>
    <inertial>
      <mass value="1.0"/>
      <origin xyz="0 0 0"/>
      <inertia ixx="0.02" ixy="0" ixz="0" iyy="0.02" iyz="0" izz="0.02"/>
    </inertial>
  </link>
  <!-- Wheel front -->
  <joint name="rf_wheel_front_joint" type="revolute">
    <parent link="rf_foot"/>
    <child link="rf_wheel_front"/>
    <origin xyz="0.105 0 0"/>
    <axis xyz="0 0 1"/>
    <limit effort="100" lower="-100" upper="100" velocity="1.0"/>
    <dynamics damping="0.1" friction="0.1"/>
  </joint>
  <link name="rf_wheel_front">
    <visual>
      <geometry>
        <mesh filename="package://hebi_robot/my_CAD/wheel.stl" scale="0.001 0.001 0.001"/>
      </geometry>
      <origin rpy="-1.5707963267948966 -1.5707963267948966 0" xyz="0 0 0"/>
      <material name="silver">
        <color rgba="0.75 0.75 0.75 1"/>
      </material>
    </visual>
    <collision>
      <geometry>
        <mesh filename="package://hebi_robot/my_CAD/wheel.stl" scale="0.001 0.001 0.001"/>
      </geometry>
      <origin xyz="0 0 0"/>
    </collision>
    <inertial>
      <mass value="1.0"/>
      <origin xyz="0 0 0"/>
      <inertia ixx="0.02" ixy="0" ixz="0" iyy="0.02" iyz="0" izz="0.02"/>
    </inertial>
  </link>
  <!-- Wheel rear -->
  <joint name="rf_wheel_rear_joint" type="revolute">
    <parent link="rf_foot"/>
    <child link="rf_wheel_rear"/>
    <origin xyz="0 0.0 0"/>
    <axis xyz="0 0 1"/>
    <limit effort="100" lower="-100" upper="100" velocity="1.0"/>
    <dynamics damping="0.1" friction="0.1"/>
  </joint>
  <link name="rf_wheel_rear">
    <visual>
      <geometry>
        <mesh filename="package://hebi_robot/my_CAD/wheel.stl" scale="0.001 0.001 0.001"/>
      </geometry>
      <origin rpy="-1.5707963267948966 -1.5707963267948966 0" xyz="0 0 0"/>
      <material name="silver">
        <color rgba="0.75 0.75 0.75 1"/>
      </material>
    </visual>
    <collision>
      <geometry>
        <mesh filename="package://hebi_robot/my_CAD/wheel.stl" scale="0.001 0.001 0.001"/>
      </geometry>
      <origin xyz="0 0 0"/>
    </collision>
    <inertial>
      <mass value="1.0"/>
      <origin xyz="0 0 0"/>
      <inertia ixx="0.02" ixy="0" ixz="0" iyy="0.02" iyz="0" izz="0.02"/>
    </inertial>
  </link>
  <!-- Shoulder -->
  <joint name="lr_shoulder1_joint" type="revolute">
    <parent link="base_link"/>
    <child link="lr_shoulder"/>
    <origin rpy="0 1.5707963267948966 0" xyz="-0.075 -0.125 0"/>
    <axis xyz="0 0 1"/>
    <limit effort="100" lower="-1.5707963267948966" upper="1.5707963267948966" velocity="1.0"/>
    <dynamics damping="0.5" friction="0.2"/>
  </joint>
  <link name="lr_shoulder">
    <visual>
      <geometry>
        <mesh filename="package://hebi_robot/my_CAD/shoulder.stl" scale="0.01 0.01 0.01"/>
      </geometry>
      <origin rpy="-1.5707963267948966 0 1.5707963267948966" xyz="0 0 0"/>
      <material name="black">
        <color rgba="0 0 0 1"/>
      </material>
    </visual>
    <collision>
      <geometry>
        <mesh filename="package://hebi_robot/my_CAD/shoulder.stl" scale="0.01 0.01 0.01"/>
      </geometry>
    </collision>
    <inertial>
      <mass value="0.5"/>
      <origin xyz="0 0 0"/>
      <inertia ixx="0.01" ixy="0" ixz="0" iyy="0.01" iyz="0" izz="0.01"/>
    </inertial>
  </link>
  <!-- Fixed joint to leg -->
  <joint name="lr_shoulder2_joint" type="fixed">
    <parent link="lr_shoulder"/>
    <child link="lr_leg"/>
    <origin xyz="0 0 0"/>
  </joint>
  <link name="lr_leg">
    <visual>
      <geometry>
        <cylinder length="0.1" radius="0.0125"/>
      </geometry>
      <origin rpy="0 -1.5707963267948966 0" xyz="0.095 0 0"/>
      <material name="silver">
        <color rgba="0.75 0.75 0.75 1"/>
      </material>
    </visual>
    <collision>
      <geometry>
        <cylinder length="0.1" radius="0.01"/>
      </geometry>
    </collision>
    <inertial>
      <mass value="1.0"/>
      <origin xyz="0 0 0"/>
      <inertia ixx="0.02" ixy="0" ixz="0" iyy="0.02" iyz="0" izz="0.02"/>
    </inertial>
  </link>
  <!-- Prismatic suspension -->
  <joint name="lr_suspention_ext_joint" type="prismatic">
    <parent link="lr_leg"/>
    <child link="lr_leg_ext"/>
    <origin xyz="0 0 0"/>
    <axis xyz="1 0 0"/>
    <limit effort="100" lower="0.0" upper="0.075" velocity="10"/>
    <dynamics damping="0.1" friction="0.1"/>
  </joint>
  <link name="lr_leg_ext">
    <visual>
      <geometry>
        <cylinder length="0.1" radius="0.0075"/>
      </geometry>
      <origin rpy="0 1.5707963267948966 0" xyz="0.1 0 0"/>
      <material name="silver">
        <color rgba="0.75 0.75 0.75 1"/>
      </material>
    </visual>
    <collision>
      <geometry>
        <cylinder length="0.1" radius="0.01"/>
      </geometry>
    </collision>
    <inertial>
      <mass value="1.0"/>
      <origin rpy="0 1.5707963267948966 0" xyz="0 0 0"/>
      <inertia ixx="0.02" ixy="0" ixz="0" iyy="0.02" iyz="0" izz="0.02"/>
    </inertial>
  </link>
  <!-- Foot pitch -->
  <joint name="lr_foot_joint_pitch" type="revolute">
    <parent link="lr_leg_ext"/>
    <child link="lr_foot_r"/>
    <origin rpy="0 0 1.5707963267948966" xyz="0.155 0 0"/>
    <axis xyz="0 0 1"/>
    <limit effort="100" lower="-1.0471975511965976" upper="1.0471975511965976" velocity="1.0"/>
    <dynamics damping="0.1" friction="0.1"/>
  </joint>
  <link name="lr_foot_r">
    <visual>
      <geometry>
        <sphere radius="0.01"/>
      </geometry>
      <origin xyz="0 0.0 0"/>
      <material name="silver">
        <color rgba="0.75 0.75 0.75 1"/>
      </material>
    </visual>
    <collision>
      <geometry>
        <sphere radius="0.01"/>
      </geometry>
      <origin xyz="0 0 0"/>
    </collision>
    <inertial>
      <mass value="1.0"/>
      <origin xyz="0 0 0"/>
      <inertia ixx="0.02" ixy="0" ixz="0" iyy="0.02" iyz="0" izz="0.02"/>
    </inertial>
  </link>
  <!-- Foot pitch to fix -->
  <joint name="lr_foot_joint_mid" type="fixed">
    <parent link="lr_foot_r"/>
    <child link="lr_foot_mid"/>
    <origin rpy="0 1.5707963267948966 0" xyz="0 0 0"/>
  </joint>
  <link name="lr_foot_mid">
    <visual>
      <geometry>
        <cylinder length="0.025" radius="0.001"/>
      </geometry>
      <origin rpy="0 1.5707963267948966 0" xyz="0.015 0 0"/>
      <material name="silver">
        <color rgba="0.75 0.75 0.75 1"/>
      </material>
    </visual>
    <collision>
      <geometry>
        <cylinder length="0.025" radius="0.001"/>
      </geometry>
      <origin rpy="0 1.5707963267948966 0" xyz="0.015 0 0"/>
    </collision>
    <inertial>
      <mass value="1.0"/>
      <origin xyz="0 0 0"/>
      <inertia ixx="0.02" ixy="0" ixz="0" iyy="0.02" iyz="0" izz="0.02"/>
    </inertial>
  </link>
  <!-- Foot fix to roll -->
  <joint name="lr_foot_joint_mid_2" type="fixed">
    <parent link="lr_foot_mid"/>
    <child link="lr_foot_mid_2"/>
    <origin rpy="0 -1.5707963267948966 0" xyz="0.025 0 0"/>
  </joint>
  <link name="lr_foot_mid_2">
    <visual>
      <geometry>
        <sphere radius="0.005"/>
      </geometry>
      <origin xyz="0 0.0 0"/>
      <material name="silver">
        <color rgba="0.75 0.75 0.75 1"/>
      </material>
    </visual>
    <collision>
      <geometry>
        <sphere radius="0.005"/>
      </geometry>
      <origin xyz="0 0 0"/>
    </collision>
    <inertial>
      <mass value="1.0"/>
      <origin xyz="0 0 0"/>
      <inertia ixx="0.02" ixy="0" ixz="0" iyy="0.02" iyz="0" izz="0.02"/>
    </inertial>
  </link>
  <!-- Foot roll -->
  <joint name="lr_foot_joint_roll" type="revolute">
    <parent link="lr_foot_mid_2"/>
    <child link="lr_foot"/>
    <origin xyz="0 0 0"/>
    <axis xyz="1 0 0"/>
    <limit effort="100" lower="-0.39269908169872414" upper="0.39269908169872414" velocity="1.0"/>
    <dynamics damping="0.1" friction="0.1"/>
  </joint>
  <link name="lr_foot">
    <visual>
      <geometry>
        <cylinder length="0.1" radius="0.001"/>
      </geometry>
      <origin rpy="0 -1.5707963267948966 0" xyz="0.05 0 0"/>
      <material name="silver">
        <color rgba="0.75 0.75 0.75 1"/>
      </material>
    </visual>
    <collision>
      <geometry>
        <cylinder length="0.1" radius="0.015"/>
      </geometry>
      <origin xyz="0.05 0.0 -0.025"/>
    </collision>
    <inertial>
      <mass value="1.0"/>
      <origin xyz="0 0 0"/>
      <inertia ixx="0.02" ixy="0" ixz="0" iyy="0.02" iyz="0" izz="0.02"/>
    </inertial>
  </link>
  <!-- Wheel front -->
  <joint name="lr_wheel_front_joint" type="revolute">
    <parent link="lr_foot"/>
    <child link="lr_wheel_front"/>
    <origin xyz="0.105 0 0"/>
    <axis xyz="0 0 1"/>
    <limit effort="100" lower="-100" upper="100" velocity="1.0"/>
    <dynamics damping="0.1" friction="0.1"/>
  </joint>
  <link name="lr_wheel_front">
    <visual>
      <geometry>
        <mesh filename="package://hebi_robot/my_CAD/wheel.stl" scale="0.001 0.001 0.001"/>
      </geometry>
      <origin rpy="-1.5707963267948966 1.5707963267948966 0" xyz="0 0 0"/>
      <material name="silver">
        <color rgba="0.75 0.75 0.75 1"/>
      </material>
    </visual>
    <collision>
      <geometry>
        <mesh filename="package://hebi_robot/my_CAD/wheel.stl" scale="0.001 0.001 0.001"/>
      </geometry>
      <origin xyz="0 0 0"/>
    </collision>
    <inertial>
      <mass value="1.0"/>
      <origin xyz="0 0 0"/>
      <inertia ixx="0.02" ixy="0" ixz="0" iyy="0.02" iyz="0" izz="0.02"/>
    </inertial>
  </link>
  <!-- Wheel rear -->
  <joint name="lr_wheel_rear_joint" type="revolute">
    <parent link="lr_foot"/>
    <child link="lr_wheel_rear"/>
    <origin xyz="0 0.0 0"/>
    <axis xyz="0 0 1"/>
    <limit effort="100" lower="-100" upper="100" velocity="1.0"/>
    <dynamics damping="0.1" friction="0.1"/>
  </joint>
  <link name="lr_wheel_rear">
    <visual>
      <geometry>
        <mesh filename="package://hebi_robot/my_CAD/wheel.stl" scale="0.001 0.001 0.001"/>
      </geometry>
      <origin rpy="-1.5707963267948966 1.5707963267948966 0" xyz="0 0 0"/>
      <material name="silver">
        <color rgba="0.75 0.75 0.75 1"/>
      </material>
    </visual>
    <collision>
      <geometry>
        <mesh filename="package://hebi_robot/my_CAD/wheel.stl" scale="0.001 0.001 0.001"/>
      </geometry>
      <origin xyz="0 0 0"/>
    </collision>
    <inertial>
      <mass value="1.0"/>
      <origin xyz="0 0 0"/>
      <inertia ixx="0.02" ixy="0" ixz="0" iyy="0.02" iyz="0" izz="0.02"/>
    </inertial>
  </link>
  <!-- Shoulder -->
  <joint name="rr_shoulder1_joint" type="revolute">
    <parent link="base_link"/>
    <child link="rr_shoulder"/>
    <origin rpy="0 1.5707963267948966 0" xyz="0.075 -0.125 0"/>
    <axis xyz="0 0 1"/>
    <limit effort="100" lower="-1.5707963267948966" upper="1.5707963267948966" velocity="1.0"/>
    <dynamics damping="0.5" friction="0.2"/>
  </joint>
  <link name="rr_shoulder">
    <visual>
      <geometry>
        <mesh filename="package://hebi_robot/my_CAD/shoulder.stl" scale="0.01 0.01 0.01"/>
      </geometry>
      <origin rpy="-1.5707963267948966 0 1.5707963267948966" xyz="0 0 0"/>
      <material name="black">
        <color rgba="0 0 0 1"/>
      </material>
    </visual>
    <collision>
      <geometry>
        <mesh filename="package://hebi_robot/my_CAD/shoulder.stl" scale="0.01 0.01 0.01"/>
      </geometry>
    </collision>
    <inertial>
      <mass value="0.5"/>
      <origin xyz="0 0 0"/>
      <inertia ixx="0.01" ixy="0" ixz="0" iyy="0.01" iyz="0" izz="0.01"/>
    </inertial>
  </link>
  <!-- Fixed joint to leg -->
  <joint name="rr_shoulder2_joint" type="fixed">
    <parent link="rr_shoulder"/>
    <child link="rr_leg"/>
    <origin xyz="0 0 0"/>
  </joint>
  <link name="rr_leg">
    <visual>
      <geometry>
        <cylinder length="0.1" radius="0.0125"/>
      </geometry>
      <origin rpy="0 -1.5707963267948966 0" xyz="0.095 0 0"/>
      <material name="silver">
        <color rgba="0.75 0.75 0.75 1"/>
      </material>
    </visual>
    <collision>
      <geometry>
        <cylinder length="0.1" radius="0.01"/>
      </geometry>
    </collision>
    <inertial>
      <mass value="1.0"/>
      <origin xyz="0 0 0"/>
      <inertia ixx="0.02" ixy="0" ixz="0" iyy="0.02" iyz="0" izz="0.02"/>
    </inertial>
  </link>
  <!-- Prismatic suspension -->
  <joint name="rr_suspention_ext_joint" type="prismatic">
    <parent link="rr_leg"/>
    <child link="rr_leg_ext"/>
    <origin xyz="0 0 0"/>
    <axis xyz="1 0 0"/>
    <limit effort="100" lower="0.0" upper="0.075" velocity="10"/>
    <dynamics damping="0.1" friction="0.1"/>
  </joint>
  <link name="rr_leg_ext">
    <visual>
      <geometry>
        <cylinder length="0.1" radius="0.0075"/>
      </geometry>
      <origin rpy="0 1.5707963267948966 0" xyz="0.1 0 0"/>
      <material name="silver">
        <color rgba="0.75 0.75 0.75 1"/>
      </material>
    </visual>
    <collision>
      <geometry>
        <cylinder length="0.1" radius="0.01"/>
      </geometry>
    </collision>
    <inertial>
      <mass value="1.0"/>
      <origin rpy="0 1.5707963267948966 0" xyz="0 0 0"/>
      <inertia ixx="0.02" ixy="0" ixz="0" iyy="0.02" iyz="0" izz="0.02"/>
    </inertial>
  </link>
  <!-- Foot pitch -->
  <joint name="rr_foot_joint_pitch" type="revolute">
    <parent link="rr_leg_ext"/>
    <child link="rr_foot_r"/>
    <origin rpy="0 0 1.5707963267948966" xyz="0.155 0 0"/>
    <axis xyz="0 0 1"/>
    <limit effort="100" lower="-1.0471975511965976" upper="1.0471975511965976" velocity="1.0"/>
    <dynamics damping="0.1" friction="0.1"/>
  </joint>
  <link name="rr_foot_r">
    <visual>
      <geometry>
        <sphere radius="0.01"/>
      </geometry>
      <origin xyz="0 0.0 0"/>
      <material name="silver">
        <color rgba="0.75 0.75 0.75 1"/>
      </material>
    </visual>
    <collision>
      <geometry>
        <sphere radius="0.01"/>
      </geometry>
      <origin xyz="0 0 0"/>
    </collision>
    <inertial>
      <mass value="1.0"/>
      <origin xyz="0 0 0"/>
      <inertia ixx="0.02" ixy="0" ixz="0" iyy="0.02" iyz="0" izz="0.02"/>
    </inertial>
  </link>
  <!-- Foot pitch to fix -->
  <joint name="rr_foot_joint_mid" type="fixed">
    <parent link="rr_foot_r"/>
    <child link="rr_foot_mid"/>
    <origin rpy="0 1.5707963267948966 0" xyz="0 0 0"/>
  </joint>
  <link name="rr_foot_mid">
    <visual>
      <geometry>
        <cylinder length="0.025" radius="0.001"/>
      </geometry>
      <origin rpy="0 1.5707963267948966 0" xyz="-0.015 0 0"/>
      <material name="silver">
        <color rgba="0.75 0.75 0.75 1"/>
      </material>
    </visual>
    <collision>
      <geometry>
        <cylinder length="0.025" radius="0.001"/>
      </geometry>
      <origin rpy="0 1.5707963267948966 0" xyz="-0.015 0 0"/>
    </collision>
    <inertial>
      <mass value="1.0"/>
      <origin xyz="0 0 0"/>
      <inertia ixx="0.02" ixy="0" ixz="0" iyy="0.02" iyz="0" izz="0.02"/>
    </inertial>
  </link>
  <!-- Foot fix to roll -->
  <joint name="rr_foot_joint_mid_2" type="fixed">
    <parent link="rr_foot_mid"/>
    <child link="rr_foot_mid_2"/>
    <origin rpy="0 -1.5707963267948966 0" xyz="-0.025 0 0"/>
  </joint>
  <link name="rr_foot_mid_2">
    <visual>
      <geometry>
        <sphere radius="0.005"/>
      </geometry>
      <origin xyz="0 0.0 0"/>
      <material name="silver">
        <color rgba="0.75 0.75 0.75 1"/>
      </material>
    </visual>
    <collision>
      <geometry>
        <sphere radius="0.005"/>
      </geometry>
      <origin xyz="0 0 0"/>
    </collision>
    <inertial>
      <mass value="1.0"/>
      <origin xyz="0 0 0"/>
      <inertia ixx="0.02" ixy="0" ixz="0" iyy="0.02" iyz="0" izz="0.02"/>
    </inertial>
  </link>
  <!-- Foot roll -->
  <joint name="rr_foot_joint_roll" type="revolute">
    <parent link="rr_foot_mid_2"/>
    <child link="rr_foot"/>
    <origin xyz="0 0 0"/>
    <axis xyz="1 0 0"/>
    <limit effort="100" lower="-0.39269908169872414" upper="0.39269908169872414" velocity="1.0"/>
    <dynamics damping="0.1" friction="0.1"/>
  </joint>
  <link name="rr_foot">
    <visual>
      <geometry>
        <cylinder length="0.1" radius="0.001"/>
      </geometry>
      <origin rpy="0 -1.5707963267948966 0" xyz="0.05 0 0"/>
      <material name="silver">
        <color rgba="0.75 0.75 0.75 1"/>
      </material>
    </visual>
    <collision>
      <geometry>
        <cylinder length="0.1" radius="0.015"/>
      </geometry>
      <origin xyz="0.05 0.0 -0.025"/>
    </collision>
    <inertial>
      <mass value="1.0"/>
      <origin xyz="0 0 0"/>
      <inertia ixx="0.02" ixy="0" ixz="0" iyy="0.02" iyz="0" izz="0.02"/>
    </inertial>
  </link>
  <!-- Wheel front -->
  <joint name="rr_wheel_front_joint" type="revolute">
    <parent link="rr_foot"/>
    <child link="rr_wheel_front"/>
    <origin xyz="0.105 0 0"/>
    <axis xyz="0 0 1"/>
    <limit effort="100" lower="-100" upper="100" velocity="1.0"/>
    <dynamics damping="0.1" friction="0.1"/>
  </joint>
  <link name="rr_wheel_front">
    <visual>
      <geometry>
        <mesh filename="package://hebi_robot/my_CAD/wheel.stl" scale="0.001 0.001 0.001"/>
      </geometry>
      <origin rpy="-1.5707963267948966 -1.5707963267948966 0" xyz="0 0 0"/>
      <material name="silver">
        <color rgba="0.75 0.75 0.75 1"/>
      </material>
    </visual>
    <collision>
      <geometry>
        <mesh filename="package://hebi_robot/my_CAD/wheel.stl" scale="0.001 0.001 0.001"/>
      </geometry>
      <origin xyz="0 0 0"/>
    </collision>
    <inertial>
      <mass value="1.0"/>
      <origin xyz="0 0 0"/>
      <inertia ixx="0.02" ixy="0" ixz="0" iyy="0.02" iyz="0" izz="0.02"/>
    </inertial>
  </link>
  <!-- Wheel rear -->
  <joint name="rr_wheel_rear_joint" type="revolute">
    <parent link="rr_foot"/>
    <child link="rr_wheel_rear"/>
    <origin xyz="0 0.0 0"/>
    <axis xyz="0 0 1"/>
    <limit effort="100" lower="-100" upper="100" velocity="1.0"/>
    <dynamics damping="0.1" friction="0.1"/>
  </joint>
  <link name="rr_wheel_rear">
    <visual>
      <geometry>
        <mesh filename="package://hebi_robot/my_CAD/wheel.stl" scale="0.001 0.001 0.001"/>
      </geometry>
      <origin rpy="-1.5707963267948966 -1.5707963267948966 0" xyz="0 0 0"/>
      <material name="silver">
        <color rgba="0.75 0.75 0.75 1"/>
      </material>
    </visual>
    <collision>
      <geometry>
        <mesh filename="package://hebi_robot/my_CAD/wheel.stl" scale="0.001 0.001 0.001"/>
      </geometry>
      <origin xyz="0 0 0"/>
    </collision>
    <inertial>
      <mass value="1.0"/>
      <origin xyz="0 0 0"/>
      <inertia ixx="0.02" ixy="0" ixz="0" iyy="0.02" iyz="0" izz="0.02"/>
    </inertial>
  </link>
  <!-- Shoulder -->
  <joint name="lf_shoulder1_joint" type="revolute">
    <parent link="base_link"/>
    <child link="lf_shoulder"/>
    <origin rpy="0 1.5707963267948966 0" xyz="-0.075 0.125 0"/>
    <axis xyz="0 0 1"/>
    <limit effort="100" lower="-1.5707963267948966" upper="1.5707963267948966" velocity="1.0"/>
    <dynamics damping="0.5" friction="0.2"/>
  </joint>
  <link name="lf_shoulder">
    <visual>
      <geometry>
        <mesh filename="package://hebi_robot/my_CAD/shoulder.stl" scale="0.01 0.01 0.01"/>
      </geometry>
      <origin rpy="-1.5707963267948966 0 1.5707963267948966" xyz="0 0 0"/>
      <material name="black">
        <color rgba="0 0 0 1"/>
      </material>
    </visual>
    <collision>
      <geometry>
        <mesh filename="package://hebi_robot/my_CAD/shoulder.stl" scale="0.01 0.01 0.01"/>
      </geometry>
    </collision>
    <inertial>
      <mass value="0.5"/>
      <origin xyz="0 0 0"/>
      <inertia ixx="0.01" ixy="0" ixz="0" iyy="0.01" iyz="0" izz="0.01"/>
    </inertial>
  </link>
  <!-- Fixed joint to leg -->
  <joint name="lf_shoulder2_joint" type="fixed">
    <parent link="lf_shoulder"/>
    <child link="lf_leg"/>
    <origin xyz="0 0 0"/>
  </joint>
  <link name="lf_leg">
    <visual>
      <geometry>
        <cylinder length="0.1" radius="0.0125"/>
      </geometry>
      <origin rpy="0 -1.5707963267948966 0" xyz="0.095 0 0"/>
      <material name="silver">
        <color rgba="0.75 0.75 0.75 1"/>
      </material>
    </visual>
    <collision>
      <geometry>
        <cylinder length="0.1" radius="0.01"/>
      </geometry>
    </collision>
    <inertial>
      <mass value="1.0"/>
      <origin xyz="0 0 0"/>
      <inertia ixx="0.02" ixy="0" ixz="0" iyy="0.02" iyz="0" izz="0.02"/>
    </inertial>
  </link>
  <!-- Prismatic suspension -->
  <joint name="lf_suspention_ext_joint" type="prismatic">
    <parent link="lf_leg"/>
    <child link="lf_leg_ext"/>
    <origin xyz="0 0 0"/>
    <axis xyz="1 0 0"/>
    <limit effort="100" lower="0.0" upper="0.075" velocity="10"/>
    <dynamics damping="0.1" friction="0.1"/>
  </joint>
  <link name="lf_leg_ext">
    <visual>
      <geometry>
        <cylinder length="0.1" radius="0.0075"/>
      </geometry>
      <origin rpy="0 1.5707963267948966 0" xyz="0.1 0 0"/>
      <material name="silver">
        <color rgba="0.75 0.75 0.75 1"/>
      </material>
    </visual>
    <collision>
      <geometry>
        <cylinder length="0.1" radius="0.01"/>
      </geometry>
    </collision>
    <inertial>
      <mass value="1.0"/>
      <origin rpy="0 1.5707963267948966 0" xyz="0 0 0"/>
      <inertia ixx="0.02" ixy="0" ixz="0" iyy="0.02" iyz="0" izz="0.02"/>
    </inertial>
  </link>
  <!-- Foot pitch -->
  <joint name="lf_foot_joint_pitch" type="revolute">
    <parent link="lf_leg_ext"/>
    <child link="lf_foot_r"/>
    <origin rpy="0 0 1.5707963267948966" xyz="0.155 0 0"/>
    <axis xyz="0 0 1"/>
    <limit effort="100" lower="-1.0471975511965976" upper="1.0471975511965976" velocity="1.0"/>
    <dynamics damping="0.1" friction="0.1"/>
  </joint>
  <link name="lf_foot_r">
    <visual>
      <geometry>
        <sphere radius="0.01"/>
      </geometry>
      <origin xyz="0 0.0 0"/>
      <material name="silver">
        <color rgba="0.75 0.75 0.75 1"/>
      </material>
    </visual>
    <collision>
      <geometry>
        <sphere radius="0.01"/>
      </geometry>
      <origin xyz="0 0 0"/>
    </collision>
    <inertial>
      <mass value="1.0"/>
      <origin xyz="0 0 0"/>
      <inertia ixx="0.02" ixy="0" ixz="0" iyy="0.02" iyz="0" izz="0.02"/>
    </inertial>
  </link>
  <!-- Foot pitch to fix -->
  <joint name="lf_foot_joint_mid" type="fixed">
    <parent link="lf_foot_r"/>
    <child link="lf_foot_mid"/>
    <origin rpy="0 1.5707963267948966 0" xyz="0 0 0"/>
  </joint>
  <link name="lf_foot_mid">
    <visual>
      <geometry>
        <cylinder length="0.025" radius="0.001"/>
      </geometry>
      <origin rpy="0 1.5707963267948966 0" xyz="0.015 0 0"/>
      <material name="silver">
        <color rgba="0.75 0.75 0.75 1"/>
      </material>
    </visual>
    <collision>
      <geometry>
        <cylinder length="0.025" radius="0.001"/>
      </geometry>
      <origin rpy="0 1.5707963267948966 0" xyz="0.015 0 0"/>
    </collision>
    <inertial>
      <mass value="1.0"/>
      <origin xyz="0 0 0"/>
      <inertia ixx="0.02" ixy="0" ixz="0" iyy="0.02" iyz="0" izz="0.02"/>
    </inertial>
  </link>
  <!-- Foot fix to roll -->
  <joint name="lf_foot_joint_mid_2" type="fixed">
    <parent link="lf_foot_mid"/>
    <child link="lf_foot_mid_2"/>
    <origin rpy="0 -1.5707963267948966 0" xyz="0.025 0 0"/>
  </joint>
  <link name="lf_foot_mid_2">
    <visual>
      <geometry>
        <sphere radius="0.005"/>
      </geometry>
      <origin xyz="0 0.0 0"/>
      <material name="silver">
        <color rgba="0.75 0.75 0.75 1"/>
      </material>
    </visual>
    <collision>
      <geometry>
        <sphere radius="0.005"/>
      </geometry>
      <origin xyz="0 0 0"/>
    </collision>
    <inertial>
      <mass value="1.0"/>
      <origin xyz="0 0 0"/>
      <inertia ixx="0.02" ixy="0" ixz="0" iyy="0.02" iyz="0" izz="0.02"/>
    </inertial>
  </link>
  <!-- Foot roll -->
  <joint name="lf_foot_joint_roll" type="revolute">
    <parent link="lf_foot_mid_2"/>
    <child link="lf_foot"/>
    <origin xyz="0 0 0"/>
    <axis xyz="1 0 0"/>
    <limit effort="100" lower="-0.39269908169872414" upper="0.39269908169872414" velocity="1.0"/>
    <dynamics damping="0.1" friction="0.1"/>
  </joint>
  <link name="lf_foot">
    <visual>
      <geometry>
        <cylinder length="0.1" radius="0.001"/>
      </geometry>
      <origin rpy="0 -1.5707963267948966 0" xyz="0.05 0 0"/>
      <material name="silver">
        <color rgba="0.75 0.75 0.75 1"/>
      </material>
    </visual>
    <collision>
      <geometry>
        <cylinder length="0.1" radius="0.015"/>
      </geometry>
      <origin xyz="0.05 0.0 -0.025"/>
    </collision>
    <inertial>
      <mass value="1.0"/>
      <origin xyz="0 0 0"/>
      <inertia ixx="0.02" ixy="0" ixz="0" iyy="0.02" iyz="0" izz="0.02"/>
    </inertial>
  </link>
  <!-- Wheel front -->
  <joint name="lf_wheel_front_joint" type="revolute">
    <parent link="lf_foot"/>
    <child link="lf_wheel_front"/>
    <origin xyz="0.105 0 0"/>
    <axis xyz="0 0 1"/>
    <limit effort="100" lower="-100" upper="100" velocity="1.0"/>
    <dynamics damping="0.1" friction="0.1"/>
  </joint>
  <link name="lf_wheel_front">
    <visual>
      <geometry>
        <mesh filename="package://hebi_robot/my_CAD/wheel.stl" scale="0.001 0.001 0.001"/>
      </geometry>
      <origin rpy="-1.5707963267948966 1.5707963267948966 0" xyz="0 0 0"/>
      <material name="silver">
        <color rgba="0.75 0.75 0.75 1"/>
      </material>
    </visual>
    <collision>
      <geometry>
        <mesh filename="package://hebi_robot/my_CAD/wheel.stl" scale="0.001 0.001 0.001"/>
      </geometry>
      <origin xyz="0 0 0"/>
    </collision>
    <inertial>
      <mass value="1.0"/>
      <origin xyz="0 0 0"/>
      <inertia ixx="0.02" ixy="0" ixz="0" iyy="0.02" iyz="0" izz="0.02"/>
    </inertial>
  </link>
  <!-- Wheel rear -->
  <joint name="lf_wheel_rear_joint" type="revolute">
    <parent link="lf_foot"/>
    <child link="lf_wheel_rear"/>
    <origin xyz="0 0.0 0"/>
    <axis xyz="0 0 1"/>
    <limit effort="100" lower="-100" upper="100" velocity="1.0"/>
    <dynamics damping="0.1" friction="0.1"/>
  </joint>
  <link name="lf_wheel_rear">
    <visual>
      <geometry>
        <mesh filename="package://hebi_robot/my_CAD/wheel.stl" scale="0.001 0.001 0.001"/>
      </geometry>
      <origin rpy="-1.5707963267948966 1.5707963267948966 0" xyz="0 0 0"/>
      <material name="silver">
        <color rgba="0.75 0.75 0.75 1"/>
      </material>
    </visual>
    <collision>
      <geometry>
        <mesh filename="package://hebi_robot/my_CAD/wheel.stl" scale="0.001 0.001 0.001"/>
      </geometry>
      <origin xyz="0 0 0"/>
    </collision>
    <inertial>
      <mass value="1.0"/>
      <origin xyz="0 0 0"/>
      <inertia ixx="0.02" ixy="0" ixz="0" iyy="0.02" iyz="0" izz="0.02"/>
    </inertial>
  </link>

  <!-- Transmissions -->
  <transmission name="rf_shoulder1_trans">
    <type>transmission_interface/SimpleTransmission</type>
    <joint name="rf_shoulder1_joint">
      <hardwareInterface>EffortJointInterface</hardwareInterface>
    </joint>
    <actuator name="rf_shoulder1_motor"/>
  </transmission>

  <transmission name="rf_foot_joint_pitch_trans">
    <type>transmission_interface/SimpleTransmission</type>
    <joint name="rf_foot_joint_pitch">
      <hardwareInterface>EffortJointInterface</hardwareInterface>
    </joint>
    <actuator name="rf_foot_joint_pitch_motor"/>
  </transmission>

  <transmission name="rf_foot_joint_roll_trans">
    <type>transmission_interface/SimpleTransmission</type>
    <joint name="rf_foot_joint_roll">
      <hardwareInterface>EffortJointInterface</hardwareInterface>
    </joint>
    <actuator name="rf_foot_joint_roll_motor"/>
  </transmission>

  <transmission name="rf_wheel_front_trans">
    <type>transmission_interface/SimpleTransmission</type>
    <joint name="rf_wheel_front_joint">
      <hardwareInterface>EffortJointInterface</hardwareInterface>
    </joint>
    <actuator name="rf_wheel_front_motor"/>
  </transmission>

  <transmission name="rf_wheel_rear_trans">
    <type>transmission_interface/SimpleTransmission</type>
    <joint name="rf_wheel_rear_joint">
      <hardwareInterface>EffortJointInterface</hardwareInterface>
    </joint>
    <actuator name="rf_wheel_rear_motor"/>
  </transmission>

  <transmission name="lr_shoulder1_trans">
    <type>transmission_interface/SimpleTransmission</type>
    <joint name="lr_shoulder1_joint">
      <hardwareInterface>EffortJointInterface</hardwareInterface>
    </joint>
    <actuator name="lr_shoulder1_motor"/>
  </transmission>

  <transmission name="lr_foot_joint_pitch_trans">
    <type>transmission_interface/SimpleTransmission</type>
    <joint name="lr_foot_joint_pitch">
      <hardwareInterface>EffortJointInterface</hardwareInterface>
    </joint>
    <actuator name="lr_foot_joint_pitch_motor"/>
  </transmission>

  <transmission name="lr_foot_joint_roll_trans">
    <type>transmission_interface/SimpleTransmission</type>
    <joint name="lr_foot_joint_roll">
      <hardwareInterface>EffortJointInterface</hardwareInterface>
    </joint>
    <actuator name="lr_foot_joint_roll_motor"/>
  </transmission>

  <transmission name="lr_wheel_front_trans">
    <type>transmission_interface/SimpleTransmission</type>
    <joint name="lr_wheel_front_joint">
      <hardwareInterface>EffortJointInterface</hardwareInterface>
    </joint>
    <actuator name="lr_wheel_front_motor"/>
  </transmission>

  <transmission name="lr_wheel_rear_trans">
    <type>transmission_interface/SimpleTransmission</type>
    <joint name="lr_wheel_rear_joint">
      <hardwareInterface>EffortJointInterface</hardwareInterface>
    </joint>
    <actuator name="lr_wheel_rear_motor"/>
  </transmission>

  <transmission name="rr_shoulder1_trans">
    <type>transmission_interface/SimpleTransmission</type>
    <joint name="rr_shoulder1_joint">
      <hardwareInterface>EffortJointInterface</hardwareInterface>
    </joint>
    <actuator name="rr_shoulder1_motor"/>
  </transmission>

  <transmission name="rr_foot_joint_pitch_trans">
    <type>transmission_interface/SimpleTransmission</type>
    <joint name="rr_foot_joint_pitch">
      <hardwareInterface>EffortJointInterface</hardwareInterface>
    </joint>
    <actuator name="rr_foot_joint_pitch_motor"/>
  </transmission>

  <transmission name="rr_foot_joint_roll_trans">
    <type>transmission_interface/SimpleTransmission</type>
    <joint name="rr_foot_joint_roll">
      <hardwareInterface>EffortJointInterface</hardwareInterface>
    </joint>
    <actuator name="rr_foot_joint_roll_motor"/>
  </transmission>

  <transmission name="rr_wheel_front_trans">
    <type>transmission_interface/SimpleTransmission</type>
    <joint name="rr_wheel_front_joint">
      <hardwareInterface>EffortJointInterface</hardwareInterface>
    </joint>
    <actuator name="rr_wheel_front_motor"/>
  </transmission>

  <transmission name="rr_wheel_rear_trans">
    <type>transmission_interface/SimpleTransmission</type>
    <joint name="rr_wheel_rear_joint">
      <hardwareInterface>EffortJointInterface</hardwareInterface>
    </joint>
    <actuator name="rr_wheel_rear_motor"/>
  </transmission>

  <transmission name="lf_shoulder1_trans">
    <type>transmission_interface/SimpleTransmission</type>
    <joint name="lf_shoulder1_joint">
      <hardwareInterface>EffortJointInterface</hardwareInterface>
    </joint>
    <actuator name="lf_shoulder1_motor"/>
  </transmission>

  <transmission name="lf_foot_joint_pitch_trans">
    <type>transmission_interface/SimpleTransmission</type>
    <joint name="lf_foot_joint_pitch">
      <hardwareInterface>EffortJointInterface</hardwareInterface>
    </joint>
    <actuator name="lf_foot_joint_pitch_motor"/>
  </transmission>

  <transmission name="lf_foot_joint_roll_trans">
    <type>transmission_interface/SimpleTransmission</type>
    <joint name="lf_foot_joint_roll">
      <hardwareInterface>EffortJointInterface</hardwareInterface>
    </joint>
    <actuator name="lf_foot_joint_roll_motor"/>
  </transmission>

  <transmission name="lf_wheel_front_trans">
    <type>transmission_interface/SimpleTransmission</type>
    <joint name="lf_wheel_front_joint">
      <hardwareInterface>EffortJointInterface</hardwareInterface>
    </joint>
    <actuator name="lf_wheel_front_motor"/>
  </transmission>

  <transmission name="lf_wheel_rear_trans">
    <type>transmission_interface/SimpleTransmission</type>
    <joint name="lf_wheel_rear_joint">
      <hardwareInterface>EffortJointInterface</hardwareInterface>
    </joint>
    <actuator name="lf_wheel_rear_motor"/>
  </transmission>


</robot>
